12/08/21 15:06: Traceback (most recent call last):
  File "/src/core/startUp.py", line 106, in <module>
    t.sleep(10)
KeyboardInterrupt
12/08/21 15:07: Traceback (most recent call last):
  File "/src/core/startUp.py", line 75, in <module>
    sdfsdf = dfsdfsdf
NameError: name 'dfsdfsdf' is not defined
12/08/21 15:09: Traceback (most recent call last):
  File "/src/core/startUp.py", line 74, in <module>
    msg.error('Boolean to str error', GFI(CF()).lineno, None, 'pfe', exitFlag)
NameError: name 'GFI' is not defined
12/08/21 15:09: Traceback (most recent call last):
  File "/src/core/startUp.py", line 76, in <module>
    msg.error('Boolean to str error', GFI(CF()).lineno, None, 'pfe', exitFlag)
  File "/src/libraries/logAndError.py", line 76, in error
    message = '%s: %s, line %s' %(timeSterrModeamp, message, lineNumber)
NameError: name 'timeSterrModeamp' is not defined
12/08/21 15:10: Boolean to str error, line 76 - Ending Program...
12/08/21 15:10: Traceback (most recent call last):
  File "/src/core/startUp.py", line 78, in <module>
    sdfsdf = dfsdfsdf
NameError: name 'dfsdfsdf' is not defined
12/08/21 15:14: Test error, line 76 - Ending Program...
12/08/21 15:17: Traceback (most recent call last):
  File "/src/core/startUp.py", line 76, in <module>
    msg.error('Test error', GFI(CF()).lineno, None, 'pfe', exitFlag)
TypeError: error() takes from 2 to 5 positional arguments but 6 were given
12/08/21 15:18: Test error, line 76 - Ending Program...
12/08/21 15:18: Traceback (most recent call last):
  File "/src/core/startUp.py", line 115, in <module>
    t.sleep(10)
KeyboardInterrupt
12/08/21 15:20: Traceback (most recent call last):
  File "/src/core/startUp.py", line 77, in <module>
    asdfasdf =asdfasdf
NameError: name 'asdfasdf' is not defined
12/08/21 15:23: Traceback (most recent call last):
  File "/src/core/startUp.py", line 73, in <module>
    msg = logAndError.logAndError(errorFileAddress, logFileAddress, errMode, logMode)
AttributeError: type object 'logAndError' has no attribute 'logAndError'
12/08/21 15:24: Traceback (most recent call last):
  File "/src/core/startUp.py", line 76, in <module>
    asdfasdf = asdfasdf
NameError: name 'asdfasdf' is not defined
12/08/21 15:30: Traceback (most recent call last):
12/08/21 15:30:   File "/src/core/startUp.py", line 52, in <module>
12/08/21 15:30:     12/08/21 15:30: asdfasdf = asdfasdf12/08/21 15:30: 
12/08/21 15:30: NameError12/08/21 15:30: : 12/08/21 15:30: name 'asdfasdf' is not defined12/08/21 15:30: 
12/08/21 15:31: Traceback (most recent call last):
12/08/21 15:31:   File "/src/core/startUp.py", line 52, in <module>
12/08/21 15:31:     12/08/21 15:31: asdfasdf = asdfasdf12/08/21 15:31: 
12/08/21 15:31: NameError12/08/21 15:31: : 12/08/21 15:31: name 'asdfasdf' is not defined12/08/21 15:31: 
12/08/21 15:33: Traceback (most recent call last):
12/08/21 15:33:   File "/src/core/startUp.py", line 75, in <module>
12/08/21 15:33:     12/08/21 15:33: t.sleep(10)12/08/21 15:33: 
12/08/21 15:33: KeyboardInterrupt12/08/21 15:33: 12/08/21 15:33: 
12/08/21 15:44: Traceback (most recent call last):
12/08/21 15:44:   File "/src/core/startUp.py", line 75, in <module>
12/08/21 15:44:     12/08/21 15:44: commands.append(f'python { manageLocation }manage.py createsuperuser --noinput')12/08/21 15:44: 
12/08/21 15:44: KeyboardInterrupt12/08/21 15:44: 12/08/21 15:44: 
12/08/21 15:48: Exception ignored in: 12/08/21 15:48: <module 'threading' from '/usr/local/lib/python3.9/threading.py'>12/08/21 15:48: 
12/08/21 15:48: Traceback (most recent call last):
12/08/21 15:48:   File "/usr/local/lib/python3.9/threading.py", line 1448, in _shutdown
12/08/21 15:48:     12/08/21 15:48: lock.acquire()12/08/21 15:48: 
12/08/21 15:48: KeyboardInterrupt12/08/21 15:48: : 12/08/21 15:48: 12/08/21 15:48: 
12/08/21 15:48: Exception ignored in: 12/08/21 15:48: <module 'threading' from '/usr/local/lib/python3.9/threading.py'>12/08/21 15:48: 
12/08/21 15:48: Traceback (most recent call last):
12/08/21 15:48:   File "/usr/local/lib/python3.9/threading.py", line 1448, in _shutdown
12/08/21 15:48:     12/08/21 15:48: lock.acquire()12/08/21 15:48: 
12/08/21 15:48: KeyboardInterrupt12/08/21 15:48: : 12/08/21 15:48: 12/08/21 15:48: 
12/08/21 15:49: Exception ignored in: 12/08/21 15:49: <module 'threading' from '/usr/local/lib/python3.9/threading.py'>12/08/21 15:49: 
12/08/21 15:49: Traceback (most recent call last):
12/08/21 15:49:   File "/usr/local/lib/python3.9/threading.py", line 1448, in _shutdown
12/08/21 15:49:     12/08/21 15:49: lock.acquire()12/08/21 15:49: 
12/08/21 15:49: KeyboardInterrupt12/08/21 15:49: : 12/08/21 15:49: 12/08/21 15:49: 
12/08/21 15:56: Exception ignored in: 12/08/21 15:56: <module 'threading' from '/usr/local/lib/python3.9/threading.py'>12/08/21 15:56: 
12/08/21 15:56: Traceback (most recent call last):
12/08/21 15:56:   File "/usr/local/lib/python3.9/threading.py", line 1448, in _shutdown
12/08/21 15:56:     12/08/21 15:56: lock.acquire()12/08/21 15:56: 
12/08/21 15:56: KeyboardInterrupt12/08/21 15:56: : 12/08/21 15:56: 12/08/21 15:56: 
12/08/21 15:56: Exception ignored in: 12/08/21 15:56: <module 'threading' from '/usr/local/lib/python3.9/threading.py'>12/08/21 15:56: 
12/08/21 15:56: Traceback (most recent call last):
12/08/21 15:56:   File "/usr/local/lib/python3.9/threading.py", line 1448, in _shutdown
12/08/21 15:56:     12/08/21 15:56: lock.acquire()12/08/21 15:56: 
12/08/21 15:56: KeyboardInterrupt12/08/21 15:56: : 12/08/21 15:56: 12/08/21 15:56: 
12/08/21 15:57: Exception ignored in: 12/08/21 15:57: <module 'threading' from '/usr/local/lib/python3.9/threading.py'>12/08/21 15:57: 
12/08/21 15:57: Traceback (most recent call last):
12/08/21 15:57:   File "/usr/local/lib/python3.9/threading.py", line 1448, in _shutdown
12/08/21 15:57:     12/08/21 15:57: lock.acquire()12/08/21 15:57: 
12/08/21 15:57: KeyboardInterrupt12/08/21 15:57: : 12/08/21 15:57: 12/08/21 15:57: 
12/08/21 15:57: Exception ignored in: 12/08/21 15:57: <module 'threading' from '/usr/local/lib/python3.9/threading.py'>12/08/21 15:57: 
12/08/21 15:57: Traceback (most recent call last):
12/08/21 15:57:   File "/usr/local/lib/python3.9/threading.py", line 1448, in _shutdown
12/08/21 15:57:     12/08/21 15:57: lock.acquire()12/08/21 15:57: 
12/08/21 15:57: KeyboardInterrupt12/08/21 15:57: : 12/08/21 15:57: 12/08/21 15:57: 
12/08/21 16:03: Exception ignored in: 12/08/21 16:03: <module 'threading' from '/usr/local/lib/python3.9/threading.py'>12/08/21 16:03: 
12/08/21 16:03: Traceback (most recent call last):
12/08/21 16:03:   File "/usr/local/lib/python3.9/threading.py", line 1448, in _shutdown
12/08/21 16:03:     12/08/21 16:03: lock.acquire()12/08/21 16:03: 
12/08/21 16:03: KeyboardInterrupt12/08/21 16:03: : 12/08/21 16:03: 12/08/21 16:03: 
12/08/21 16:09: Exception ignored in: 12/08/21 16:09: <module 'threading' from '/usr/local/lib/python3.9/threading.py'>12/08/21 16:09: 
12/08/21 16:09: Traceback (most recent call last):
12/08/21 16:09:   File "/usr/local/lib/python3.9/threading.py", line 1448, in _shutdown
12/08/21 16:09:     12/08/21 16:09: lock.acquire()12/08/21 16:09: 
12/08/21 16:09: KeyboardInterrupt12/08/21 16:09: : 12/08/21 16:09: 12/08/21 16:09: 
12/08/21 16:12: Exception in thread 12/08/21 16:12: Thread-112/08/21 16:12: :
12/08/21 16:12: Traceback (most recent call last):
12/08/21 16:12:   File "/usr/local/lib/python3.9/threading.py", line 973, in _bootstrap_inner
12/08/21 16:12:     12/08/21 16:12: self.run()12/08/21 16:12: 
12/08/21 16:12:   File "/src/core/startUp.py", line 56, in run
12/08/21 16:12:     12/08/21 16:12: mainThread()12/08/21 16:12: 
12/08/21 16:12:   File "/src/core/startUp.py", line 86, in mainThread
12/08/21 16:12:     12/08/21 16:12: msg.log(childUpdate.read())12/08/21 16:12: 
12/08/21 16:12:   File "/usr/local/lib/python3.9/site-packages/pexpect/spawnbase.py", line 444, in read
12/08/21 16:12:     12/08/21 16:12: self.expect(self.delimiter)12/08/21 16:12: 
12/08/21 16:12:   File "/usr/local/lib/python3.9/site-packages/pexpect/spawnbase.py", line 343, in expect
12/08/21 16:12:     12/08/21 16:12: return self.expect_list(compiled_pattern_list,12/08/21 16:12: 
12/08/21 16:12:   File "/usr/local/lib/python3.9/site-packages/pexpect/spawnbase.py", line 372, in expect_list
12/08/21 16:12:     12/08/21 16:12: return exp.expect_loop(timeout)12/08/21 16:12: 
12/08/21 16:12:   File "/usr/local/lib/python3.9/site-packages/pexpect/expect.py", line 181, in expect_loop
12/08/21 16:12:     12/08/21 16:12: return self.timeout(e)12/08/21 16:12: 
12/08/21 16:12:   File "/usr/local/lib/python3.9/site-packages/pexpect/expect.py", line 144, in timeout
12/08/21 16:12:     12/08/21 16:12: raise exc12/08/21 16:12: 
12/08/21 16:12: pexpect.exceptions12/08/21 16:12: .12/08/21 16:12: TIMEOUT12/08/21 16:12: : 12/08/21 16:12: Timeout exceeded.
<pexpect.pty_spawn.spawn object at 0x7f804baae1c0>
command: /usr/local/bin/uwsgi
args: ['/usr/local/bin/uwsgi', '--emperor', '/etc/uwsgi/vassals']
buffer (last 100 chars): b'ned\r\nThu Aug 12 16:12:03 2021 - [emperor] vassal spiritumDuo_uwsgi.ini is ready to accept requests\r\n'
before (last 100 chars): b'ned\r\nThu Aug 12 16:12:03 2021 - [emperor] vassal spiritumDuo_uwsgi.ini is ready to accept requests\r\n'
after: <class 'pexpect.exceptions.TIMEOUT'>
match: None
match_index: None
exitstatus: None
flag_eof: False
pid: 58
child_fd: 7
closed: False
timeout: 10
delimiter: <class 'pexpect.exceptions.EOF'>
logfile: None
logfile_read: None
logfile_send: None
maxread: 2000
ignorecase: False
searchwindowsize: None
delaybeforesend: 0.05
delayafterclose: 0.1
delayafterterminate: 0.1
searcher: searcher_re:
    0: EOF12/08/21 16:12: 
12/08/21 16:14: Exception ignored in: 12/08/21 16:14: <module 'threading' from '/usr/local/lib/python3.9/threading.py'>12/08/21 16:14: 
12/08/21 16:14: Traceback (most recent call last):
12/08/21 16:14:   File "/usr/local/lib/python3.9/threading.py", line 1448, in _shutdown
12/08/21 16:14:     12/08/21 16:14: lock.acquire()12/08/21 16:14: 
12/08/21 16:14: KeyboardInterrupt12/08/21 16:14: : 12/08/21 16:14: 12/08/21 16:14: 
12/08/21 16:18: Exception in thread 12/08/21 16:18: Thread-112/08/21 16:18: :
12/08/21 16:18: Traceback (most recent call last):
12/08/21 16:18:   File "/usr/local/lib/python3.9/threading.py", line 973, in _bootstrap_inner
12/08/21 16:18:     12/08/21 16:18: self.run()12/08/21 16:18: 
12/08/21 16:18:   File "/src/core/startUp.py", line 56, in run
12/08/21 16:18:     12/08/21 16:18: mainThread()12/08/21 16:18: 
12/08/21 16:18:   File "/src/core/startUp.py", line 86, in mainThread
12/08/21 16:18:     12/08/21 16:18: msg.log(childUpdate.read())12/08/21 16:18: 
12/08/21 16:18: AttributeError12/08/21 16:18: : 12/08/21 16:18: 'bytes' object has no attribute 'read'12/08/21 16:18: 
12/08/21 16:19: Exception ignored in: 12/08/21 16:19: <module 'threading' from '/usr/local/lib/python3.9/threading.py'>12/08/21 16:19: 
12/08/21 16:19: Traceback (most recent call last):
12/08/21 16:19:   File "/usr/local/lib/python3.9/threading.py", line 1448, in _shutdown
12/08/21 16:19:     12/08/21 16:19: lock.acquire()12/08/21 16:19: 
12/08/21 16:19: KeyboardInterrupt12/08/21 16:19: : 12/08/21 16:19: 12/08/21 16:19: 
12/08/21 16:23: Exception ignored in: 12/08/21 16:23: <module 'threading' from '/usr/local/lib/python3.9/threading.py'>12/08/21 16:23: 
12/08/21 16:23: Traceback (most recent call last):
12/08/21 16:23:   File "/usr/local/lib/python3.9/threading.py", line 1448, in _shutdown
12/08/21 16:23:     12/08/21 16:23: lock.acquire()12/08/21 16:23: 
12/08/21 16:23: KeyboardInterrupt12/08/21 16:23: : 12/08/21 16:23: 12/08/21 16:23: 
12/08/21 16:47: Exception ignored in: 12/08/21 16:47: <module 'threading' from '/usr/local/lib/python3.9/threading.py'>12/08/21 16:47: 
12/08/21 16:47: Traceback (most recent call last):
12/08/21 16:47:   File "/usr/local/lib/python3.9/threading.py", line 1448, in _shutdown
12/08/21 16:47:     12/08/21 16:47: lock.acquire()12/08/21 16:47: 
12/08/21 16:47: KeyboardInterrupt12/08/21 16:47: : 12/08/21 16:47: 12/08/21 16:47: 
12/08/21 16:51: Exception ignored in: 12/08/21 16:51: <module 'threading' from '/usr/local/lib/python3.9/threading.py'>12/08/21 16:51: 
12/08/21 16:51: Traceback (most recent call last):
12/08/21 16:51:   File "/usr/local/lib/python3.9/threading.py", line 1448, in _shutdown
12/08/21 16:51:     12/08/21 16:51: lock.acquire()12/08/21 16:51: 
12/08/21 16:51: KeyboardInterrupt12/08/21 16:51: : 12/08/21 16:51: 12/08/21 16:51: 
12/08/21 16:55: Exception ignored in: <module 'threading' from '/usr/local/lib/python3.9/threading.py'>
Traceback (most recent call last):
  File "/usr/local/lib/python3.9/threading.py", line 1448, in _shutdown
    lock.acquire()
KeyboardInterrupt: 
12/08/21 16:56: Exception ignored in: <module 'threading' from '/usr/local/lib/python3.9/threading.py'>
Traceback (most recent call last):
  File "/usr/local/lib/python3.9/threading.py", line 1448, in _shutdown
    lock.acquire()
KeyboardInterrupt: 
12/08/21 16:57: 12/08/21 16:57: 12/08/21 16:58: 12/08/21 16:58: 12/08/21 16:59: Exception ignored in: <module 'threading' from '/usr/local/lib/python3.9/threading.py'>
Traceback (most recent call last):
  File "/usr/local/lib/python3.9/threading.py", line 1448, in _shutdown
    lock.acquire()
KeyboardInterrupt: 
12/08/21 17:02: Exception ignored in: <module 'threading' from '/usr/local/lib/python3.9/threading.py'>
Traceback (most recent call last):
  File "/usr/local/lib/python3.9/threading.py", line 1448, in _shutdown
    lock.acquire()
KeyboardInterrupt: 
12/08/21 17:02: Exception ignored in: <module 'threading' from '/usr/local/lib/python3.9/threading.py'>
Traceback (most recent call last):
  File "/usr/local/lib/python3.9/threading.py", line 1448, in _shutdown
    lock.acquire()
KeyboardInterrupt: 
12/08/21 17:03: Exception ignored in: <module 'threading' from '/usr/local/lib/python3.9/threading.py'>
Traceback (most recent call last):
  File "/usr/local/lib/python3.9/threading.py", line 1448, in _shutdown
    lock.acquire()
KeyboardInterrupt: 
12/08/21 17:04: Exception ignored in: <module 'threading' from '/usr/local/lib/python3.9/threading.py'>
Traceback (most recent call last):
  File "/usr/local/lib/python3.9/threading.py", line 1448, in _shutdown
    lock.acquire()
KeyboardInterrupt: 
12/08/21 17:05: Exception ignored in: <module 'threading' from '/usr/local/lib/python3.9/threading.py'>
Traceback (most recent call last):
  File "/usr/local/lib/python3.9/threading.py", line 1448, in _shutdown
    lock.acquire()
KeyboardInterrupt: 
12/08/21 17:05: Exception ignored in: <module 'threading' from '/usr/local/lib/python3.9/threading.py'>
Traceback (most recent call last):
  File "/usr/local/lib/python3.9/threading.py", line 1448, in _shutdown
    lock.acquire()
KeyboardInterrupt: 
12/08/21 17:05: Exception ignored in: <module 'threading' from '/usr/local/lib/python3.9/threading.py'>
Traceback (most recent call last):
  File "/usr/local/lib/python3.9/threading.py", line 1448, in _shutdown
    lock.acquire()
KeyboardInterrupt: 
12/08/21 17:07: Exception ignored in: <module 'threading' from '/usr/local/lib/python3.9/threading.py'>
Traceback (most recent call last):
  File "/usr/local/lib/python3.9/threading.py", line 1448, in _shutdown
    lock.acquire()
KeyboardInterrupt: 
12/08/21 17:12: Exception ignored in: <module 'threading' from '/usr/local/lib/python3.9/threading.py'>
Traceback (most recent call last):
  File "/usr/local/lib/python3.9/threading.py", line 1448, in _shutdown
    lock.acquire()
KeyboardInterrupt: 
12/08/21 17:14: Exception ignored in: <module 'threading' from '/usr/local/lib/python3.9/threading.py'>
Traceback (most recent call last):
  File "/usr/local/lib/python3.9/threading.py", line 1448, in _shutdown
    lock.acquire()
KeyboardInterrupt: 
12/08/21 17:16: Exception ignored in: <module 'threading' from '/usr/local/lib/python3.9/threading.py'>
Traceback (most recent call last):
  File "/usr/local/lib/python3.9/threading.py", line 1448, in _shutdown
    lock.acquire()
KeyboardInterrupt: 
12/08/21 17:18: Exception ignored in: <module 'threading' from '/usr/local/lib/python3.9/threading.py'>
Traceback (most recent call last):
  File "/usr/local/lib/python3.9/threading.py", line 1448, in _shutdown
    lock.acquire()
KeyboardInterrupt: 
12/08/21 17:21: Exception ignored in: <module 'threading' from '/usr/local/lib/python3.9/threading.py'>
Traceback (most recent call last):
  File "/usr/local/lib/python3.9/threading.py", line 1448, in _shutdown
    lock.acquire()
KeyboardInterrupt: 
12/08/21 21:37: Exception ignored in: <module 'threading' from '/usr/local/lib/python3.9/threading.py'>
Traceback (most recent call last):
  File "/usr/local/lib/python3.9/threading.py", line 1448, in _shutdown
    lock.acquire()
KeyboardInterrupt: 
12/08/21 21:38: Exception ignored in: <module 'threading' from '/usr/local/lib/python3.9/threading.py'>
Traceback (most recent call last):
  File "/usr/local/lib/python3.9/threading.py", line 1448, in _shutdown
    lock.acquire()
KeyboardInterrupt: 
